<?xml version="1.0"?>
<robot name="myfirst">
    <link name="base_link">
        <visual>
            <geometry>
                <cylinder length="2" radius="0.1"/>
            </geometry>
            <origin xyz="1 0 0" rpy="0 1.57 0" />
        </visual>
    </link>
    
    <link name="link1">
        <visual>
            <geometry>
                <cylinder length="2" radius="0.1"/>
            </geometry>
            <origin xyz="0 1 0" rpy="1.57 0 0" />
        </visual>
    </link>

    <joint name="joint1" type="continuous">
        <parent link="base_link"/>
        <child link="link1"/>
        <origin xyz="2 0 0" rpy="0 0 -1.57" />
        <axis xyz="0 0 1" />
    </joint>
</robot>
