<?xml version="1.0"?>
<robot name="tree">
    <link name="base_link">
        <visual>
            <geometry>
                <cylinder length="1" radius="0.1"/>
            </geometry>
            <origin xyz="0 0 0.5" rpy="0 0 0" />
        </visual>
    </link>
    
    <link name="link1">
        <visual>
            <geometry>
                <cylinder length="1" radius="0.1"/>
            </geometry>
            <origin xyz="0 0 0.5" rpy="0 0 0" />
        </visual>
    </link>

    <link name="link2">
        <visual>
            <geometry>
                <cylinder length="1" radius="0.1"/>
            </geometry>
            <origin xyz="0 0 0.5" rpy="0 0 0" />
        </visual>
    </link>

    
    <!-- 
    Important: We cannot have somethink like a base_joint since rviz expects
    every joint to have both a parent and a child link.
    A root joint would not have a parent and rviz would therefore throw the
    following error:
    'Failed to build tree: Joint [base_joint] is missing a parent and/or child 
    link specification.' 
    -->

    <joint name="joint1" type="continuous">
        <parent link="base_link"/>
        <child link="link1"/>
        <origin xyz="0 0 1" rpy="0 0 0" />
        <axis xyz="0.5 0.5 0" />
    </joint>

    <joint name="joint2" type="continuous">
        <parent link="link1"/>
        <child link="link2"/>
        <origin xyz="0 0 1" rpy="0 0 0" />
        <axis xyz="0.5 0.5 0" />
    </joint>
</robot>
